Workbook
Name CoreFinancials: 'New Marketecture'!$A$76:$H$139
Name RiskManagement: 'New Marketecture'!$A$250:$F$259
Name Procurement: 'New Marketecture'!$A$260:$H$288
Name AssetsInventory: 'New Marketecture'!$A$162:$H$187
Name Audit: 'New Marketecture'!$A$140:$H$160
Name FinancialInvestments: 'New Marketecture'!$A$248:$H$249
Name PIM: 'New Marketecture'!$A$331:$H$352
Name BudgetPreparation: 'New Marketecture'!$A$26:$H$61
Name SocialBenefits: 'New Marketecture'!$A$290:$H$315
Name PolicyManagement: 'New Marketecture'!$A$8:$H$25
Name Treasury: 'New Marketecture'!$A$196:$H$217
Name Grants: 'New Marketecture'!$A$316:$H$330
Name HR: 'New Marketecture'!$A$493:$H$570
Name Tax: 'New Marketecture'!$A$389:$H$449
Name Payroll: 'New Marketecture'!$A$464:$H$492
Name PerformanceTransparency: 'New Marketecture'!$A$62:$H$75
Name PBHC: 'New Marketecture'!$A$450:$H$463
Name Revenue: 'New Marketecture'!$A$346:$H$389
Name Debt: 'New Marketecture'!$A$218:$H$247

Sheet Read Me
A1: Public Financial Management Component Map
A2: Read Me
A3: Purpose
A4: • identify all possible public finance functions & associated non-financial functions (i.e. budget - policy, payroll - HR)
A5: • use the component business mapping technique
A6: • inform the FreeBalance product marketecture
A7: PFM CM Sheets
A8: PFM Component Map: Breakdown from pillar through function to component
A9: New Marketecture: Maps new product marketecture to PFMCM functions
A10: Concepts: Explains the component business mapping technique with FreeBalanc extensions
A11: Pivot Table: Analysis of components and pillars
A12: Supporting Material
... A36: Red for all transparency components that begin with X.X.T1

Sheet PFM Component Map
B1: FreeBalance Public Financial Management Component Map 4.3, 2026
A2: Pillar | B2: Function | C2: Component | D2: Type | E2: Description | F2: Public Finance Purpose | G2: =Concepts!F4 -> Activities | H2: =Concepts!F5 -> Resources | I2: =Concepts!F6 -> Governance | J2: =Concepts!F7 -> Business Services
A3: 1. Government Performance Management | B3: 1.1 Policy Management | C3: 1.1.01 Legislation Management | D3: D-RM | E3: =if(D3<>"",VLOOKUP(D3,Concepts!C$2:D$12,2,FALSE),"") -> Reform & Modernization | F3: Develop and manage internal government public finance legislation. | J3: • From: actuals, trends, previous plans, 1.1.2, 1.1.4 • To:
A4: 1. Government Performance Management | B4: 1.1 Policy Management | C4: 1.1.02 Regulation Management | D4: D-RM | E4: =if(D4<>"",VLOOKUP(D4,Concepts!C$2:D$12,2,FALSE),"") -> Reform & Modernization | F4: Develop and manage external to government regulatory environment in support of public finance objectives.
A5: 1. Government Performance Management | B5: 1.1 Policy Management | C5: 1.1.03 Development Strategy & Government Goals | D5: D-PS | E5: =if(D5<>"",VLOOKUP(D5,Concepts!C$2:D$12,2,FALSE),"") -> Planning & Scenarios | F5: Articulate government goals like national development strategies, SDGs, long-term visions and 5 year plans | G5: National plans, political platforms, budget priorities, scenario analysis | H5: Executive, planning & economic departments, budget offices, political parties, parliaments, IFIs, outreach
A6: 1. Government Performance Management | B6: 1.1 Policy Management | C6: 1.1.04 Policy Legal Framework | D6: D-RM | E6: =if(D6<>"",VLOOKUP(D6,Concepts!C$2:D$12,2,FALSE),"") -> Reform & Modernization | F6: Integrate planning with policy objectives, and legal framework | J6: • From: • To:
A7: 1. Government Performance Management | B7: 1.1 Policy Management | C7: 1.1.05 Intergovernmental Fiscal Relations | D7: D-PS | E7: =if(D7<>"",VLOOKUP(D7,Concepts!C$2:D$12,2,FALSE),"") -> Planning & Scenarios | F7: Support for fiscal relations in planning for independent agencies, sub-national governments, and SOEs | J7: • From: • To:
A8: 1. Government Performance Management | B8: 1.1 Policy Management | C8: 1.1.06 Fiscal Framework | D8: C- GC | E8: =if(D8<>"",VLOOKUP(D8,Concepts!C$2:D$12,2,FALSE),"") -> Government Controls | F8: Integrate fiscal rules & procedures in policy & budget planning.
A9: 1. Government Performance Management | B9: 1.1 Policy Management | C9: 1.1.07 Trend Analysis | D9: D-PS | E9: =if(D9<>"",VLOOKUP(D9,Concepts!C$2:D$12,2,FALSE),"") -> Planning & Scenarios | F9: Enable statistical analysis of government & economic data over time
A10: 1. Government Performance Management | B10: 1.1 Policy Management | C10: 1.1.08 Macroeconomic Forecasting | D10: D-PS | E10: =if(D10<>"",VLOOKUP(D10,Concepts!C$2:D$12,2,FALSE),"") -> Planning & Scenarios | F10: Predict potential revenue mobilization, including effects of government spending and regulations, as input to budget preparation
A11: 1. Government Performance Management | B11: 1.1 Policy Management | C11: 1.1.09 Policy Planning Versions | D11: D-PS | E11: =if(D11<>"",VLOOKUP(D11,Concepts!C$2:D$12,2,FALSE),"") -> Planning & Scenarios | F11: Support stages of policy formulation, including internal papers and reports, as input to budget planning | J11: • From: • To:
A12: 1. Government Performance Management | B12: 1.1 Policy Management | C12: 1.1.10 Policy Impact Assessment | D12: D-PS | E12: =if(D12<>"",VLOOKUP(D12,Concepts!C$2:D$12,2,FALSE),"") -> Planning & Scenarios | F12: Evaluate proposed policies for social, economic, and environmental impacts using evidence-based methodologies and scenario modeling.
A13: 1. Government Performance Management | B13: 1.1 Policy Management | C13: 1.1.11 Cross-Sectoral Policy Integration | D13: D-PS | E13: =if(D13<>"",VLOOKUP(D13,Concepts!C$2:D$12,2,FALSE),"") -> Planning & Scenarios | F13: Ensure coherence across government policies, such as climate, social protection, and economic development, to align with overarching strategic goals
A14: 1. Government Performance Management | B14: 1.1 Policy Management | C14: 1.1.12 International Commitments & Agreements | D14: C- GC | E14: =if(D14<>"",VLOOKUP(D14,Concepts!C$2:D$12,2,FALSE),"") -> Government Controls | F14: Monitor and integrate international policy commitments (e.g., SDGs, Paris Agreement, WTO obligations) into national policy planning frameworks
A15: 1. Government Performance Management | B15: 1.1 Policy Management | C15: 1.1.13 Evidence-Based Policy Evaluation | D15: C- GC | E15: =if(D15<>"",VLOOKUP(D15,Concepts!C$2:D$12,2,FALSE),"") -> Government Controls | F15: Facilitate policy impact assessments and program evaluations using empirical data to measure effectiveness and inform decision-making.
A16: 1. Government Performance Management | B16: 1.1 Policy Management | C16: 1.1.14 Public Sector Efficiency & Productivity Metrics | D16: D-PS | E16: =if(D16<>"",VLOOKUP(D16,Concepts!C$2:D$12,2,FALSE),"") -> Planning & Scenarios | F16: Identify efficiency indicators, such as cost-effectiveness, timeliness, and resource utilization, to optimize public service delivery.
A17: 1. Government Performance Management | B17: 1.1 Policy Management | C17: 1.1.A1 Policy Approvals | D17: D-AP | E17: =if(D17<>"",VLOOKUP(D17,Concepts!C$2:D$12,2,FALSE),"") -> Approvals | F17: Support policy approvals that feed into budget planning.
A18: 1. Government Performance Management | B18: 1.1 Policy Management | C18: 1.1.T1 Stakeholder Consultation & Engagement | D18: E-FT | E18: =if(D18<>"",VLOOKUP(D18,Concepts!C$2:D$12,2,FALSE),"") -> Fiscal Transparency | F18: Facilitate structured engagement with civil society, private sector, development partners, and other stakeholders to ensure inclusive policy planning. Support surveys.
A19: 1. Government Performance Management | B19: 1.1 Policy Management | C19: 1.1.T2 Policy Transparency | D19: E-FT | E19: =if(D19<>"",VLOOKUP(D19,Concepts!C$2:D$12,2,FALSE),"") -> Fiscal Transparency | F19: Support publishing of policy documents, policy information, government goals, and national development strategies
A20: 1. Government Performance Management | B20: 1.1 Policy Management | C20: 1.1.T3 Economics Transparency | D20: E-FT | E20: =if(D20<>"",VLOOKUP(D20,Concepts!C$2:D$12,2,FALSE),"") -> Fiscal Transparency | F20: Support publishing of macroeconomic analysis, fiscal assumptions, budget envelopes
A21: 1. Government Performance Management | B21: 1.2 Budget Planning / Formulation | C21: 1.2.01 Budget Legal Framework | D21: D-RM | E21: =if(D21<>"",VLOOKUP(D21,Concepts!C$2:D$12,2,FALSE),"") -> Reform & Modernization | F21: Support the legal structure, processes, fiscal rules, and schedules for budget preparation | J21: • From: • To:
A22: 1. Government Performance Management | B22: 1.2 Budget Planning / Formulation | C22: 1.2.02 Budget Circular & Budget Ceilings | D22: C- GC | E22: =if(D22<>"",VLOOKUP(D22,Concepts!C$2:D$12,2,FALSE),"") -> Government Controls | F22: Provide guidance in the development of MDA budgets, including schedule and ceilings control | J22: • From: • To:
A23: 1. Government Performance Management | B23: 1.2 Budget Planning / Formulation | C23: 1.2.03 Multiple Year Budget Formulation | D23: D-PS | E23: =if(D23<>"",VLOOKUP(D23,Concepts!C$2:D$12,2,FALSE),"") -> Planning & Scenarios | F23: Prepare 3 to 5 year budgets to coordinate spending priorities, manage multiple-year investments, and determine results. | J23: • From: • To:
A24: 1. Government Performance Management | B24: 1.2 Budget Planning / Formulation | C24: 1.2.04 Budget Planning Monitoring | D24: C-ME | E24: =if(D24<>"",VLOOKUP(D24,Concepts!C$2:D$12,2,FALSE),"") -> Monitoring & Evaluation | F24: Enable monitoring the progress of MDA budgets during formulation to provide guidance
A25: 1. Government Performance Management | B25: 1.2 Budget Planning / Formulation | C25: 1.2.05 Cost Assumptions | D25: C- GC | E25: =if(D25<>"",VLOOKUP(D25,Concepts!C$2:D$12,2,FALSE),"") -> Government Controls | F25: Leverage cost drivers and cost driver packages for more accurate projections | J25: • From: • To:
A26: 1. Government Performance Management | B26: 1.2 Budget Planning / Formulation | C26: 1.2.06 Scenario Planning | D26: D-PS | E26: =if(D26<>"",VLOOKUP(D26,Concepts!C$2:D$12,2,FALSE),"") -> Planning & Scenarios | F26: Provide forecasting and scenarios to improve budget credibility, and enable re-forecasting during budget implementation | J26: • From: • To:
A27: 1. Government Performance Management | B27: 1.2 Budget Planning / Formulation | C27: 1.2.07 Budget Calendar, Versions | D27: C- GC | E27: =if(D27<>"",VLOOKUP(D27,Concepts!C$2:D$12,2,FALSE),"") -> Government Controls | F27: Manage the budget calendar with version controls across the budget planning cycle | J27: • From: • To:
A28: 1. Government Performance Management | B28: 1.2 Budget Planning / Formulation | C28: 1.2.08 Budget Releases Rules | D28: C- GC | E28: =if(D28<>"",VLOOKUP(D28,Concepts!C$2:D$12,2,FALSE),"") -> Government Controls | F28: Support for partial budget releases when the budget is not approved or partly approved
A29: 1. Government Performance Management | B29: 1.2 Budget Planning / Formulation | C29: 1.2.09 Capital & Recurrent Expenditure Planning | D29: D-PS | E29: =if(D29<>"",VLOOKUP(D29,Concepts!C$2:D$12,2,FALSE),"") -> Planning & Scenarios | F29: Differentiate planning for capital investments and recurrent expenditures, ensuring alignment with fiscal sustainability and public investment strategies.
A30: 1. Government Performance Management | B30: 1.2 Budget Planning / Formulation | C30: 1.2.10 Climate & Sustainability Budgeting | D30: D-PS | E30: =if(D30<>"",VLOOKUP(D30,Concepts!C$2:D$12,2,FALSE),"") -> Planning & Scenarios | F30: Embed climate-responsive budgeting and sustainable development considerations into budget formulation to track green spending and adaptation investments.
A31: 1. Government Performance Management | B31: 1.2 Budget Planning / Formulation | C31: 1.2.11 Gender, Wellbeing & Social Inclusion Budgeting | D31: D-PS | E31: =if(D31<>"",VLOOKUP(D31,Concepts!C$2:D$12,2,FALSE),"") -> Planning & Scenarios | F31: Incorporate gender-responsive and inclusive budgeting methodologies to address social equity, poverty reduction, and support for vulnerable groups.
A32: 1. Government Performance Management | B32: 1.2 Budget Planning / Formulation | C32: 1.2.12 Contingency & Emergency Budget Planning | D32: D-PS | E32: =if(D32<>"",VLOOKUP(D32,Concepts!C$2:D$12,2,FALSE),"") -> Planning & Scenarios | F32: Allocate budgetary provisions for emergency response, economic shocks, and unforeseen expenditures within fiscal limits.
A33: 1. Government Performance Management | B33: 1.2 Budget Planning / Formulation | C33: 1.2.13 Development Partner & Donor Coordination | D33: D-PS | E33: =if(D33<>"",VLOOKUP(D33,Concepts!C$2:D$12,2,FALSE),"") -> Planning & Scenarios | F33: Integrate external financing, donor funds, and project support into budget formulation, ensuring alignment with national priorities and fiscal strategies.
A34: 1. Government Performance Management | B34: 1.2 Budget Planning / Formulation | C34: 1.2.14 Subnational & Intergovernmental Budgeting | D34: D-PS | E34: =if(D34<>"",VLOOKUP(D34,Concepts!C$2:D$12,2,FALSE),"") -> Planning & Scenarios | F34: Support budgeting for subnational governments and intergovernmental transfers, ensuring consistency with national fiscal policies and revenue-sharing mechanisms.
A35: 1. Government Performance Management | B35: 1.2 Budget Planning / Formulation | C35: 1.2.15 Cost-Benefit Analysis | D35: D-PS | E35: =if(D35<>"",VLOOKUP(D35,Concepts!C$2:D$12,2,FALSE),"") -> Planning & Scenarios | F35: Facilitate economic analysis of government projects, including cost-benefit analysis, return on investment (ROI), and value-for-money assessments.
A36: 1. Government Performance Management | B36: 1.2 Budget Planning / Formulation | C36: 1.2.16 PEFA Assessments | D36: C-OA | E36: =if(D36<>"",VLOOKUP(D36,Concepts!C$2:D$12,2,FALSE),"") -> Oversight & Audit | F36: Undergo Public Expenditure and Financial Accountability Assessment (PEFA) , especially PI-14 to PI-18
A37: 1. Government Performance Management | B37: 1.2 Budget Planning / Formulation | C37: 1.2.A1 Intermediate Budget Approvals | D37: D-AP | E37: =if(D37<>"",VLOOKUP(D37,Concepts!C$2:D$12,2,FALSE),"") -> Approvals | F37: Approve intermediate budgets such as division, department, ministry, and budget office prior to legislative approval
A38: 1. Government Performance Management | B38: 1.2 Budget Planning / Formulation | C38: 1.2.A2 Organic Budget Law / Vote | D38: D-AP | E38: =if(D38<>"",VLOOKUP(D38,Concepts!C$2:D$12,2,FALSE),"") -> Approvals | F38: Approve the budget for implementation after executive and legislative approval | J38: • From: • To:
A39: 1. Government Performance Management | B39: 1.2 Budget Planning / Formulation | C39: 1.2.A2 Partial Budget Release | D39: D-AP | E39: =if(D39<>"",VLOOKUP(D39,Concepts!C$2:D$12,2,FALSE),"") -> Approvals | F39: Approve partial releases complying with budget laws that requires executive and/or legislative approval
A40: 1. Government Performance Management | B40: 1.2 Budget Planning / Formulation | C40: 1.2.T1 Budget Books | D40: E-FT | E40: =if(D40<>"",VLOOKUP(D40,Concepts!C$2:D$12,2,FALSE),"") -> Fiscal Transparency | F40: Create budget documents, citizen budgets, pamphlets and other formatted output | J40: • From: • To:
...

Sheet GRC Taxonomy
A1: Governance Risk & Compliance Taxonomy
A2: • AI assisted analysis
A3: Category | C3: Explanation
A4: 1. Fiscal and Fiduciary Governance | C4: Establishes the primary control environment, ensuring the prudent management of public resources, budget reliability, and compliance with financial legislation11. It addresses the fundamental requirement that all public expenditures must be authorized, accurate, and aligned with strategic prioritie
B5: 1.1 Policy, Macro-Fiscal Planning and Budgetary Reliability | C5: Focuses on the accuracy of revenue projections, the management of structural expenditures, the containment of off-budget fiscal decisions, and the linkage to public policy objectives
B6: 1.2 Contingent Liabilities and Fiscal Risk Analytics | C6: Addresses exposures from public procurment, infrastructure projects, State-Owned Enterprises (SOEs), Public-Private Partnerships (PPPs), calls on explicit credit guarantees, and long-term debt sustainability
B7: 1.3 Credit and Debt Program Risk | C7: Mitigates public debt, credit rating, and fiscal space risks, with unique repayment, prepayment, and market risks
B8: 1.4 Fiduciary Internal Controls and Pay Administration | C8: Manages risks associated with budget and commitment controls, spending authorizations, and segregation of duties
A9: 2. Public Integrity, Compliance, and Oversight | C9: Focuses on safeguarding the public interest, preventing systemic corruption, and ensuring that public officials adhere to high ethical standards; aligns directly with the OECD Recommendation on Public Integrity
B10: 2.1 Conflicts of Interest and Ethical Standards | C10: Monitors perceived, potential, or actual conflicts between private interests and public duties, including asset declarations, lobbying, and post-employment limitations3
B11: 2.2 Anti-Corruption, Whistleblowing, and Investigation | C11: Governs systems to prevent, detect, and sanction bribery, embezzlement, fraud, and influence trading, including secure channels for whistleblowers
B12: 2.3 External Scrutiny, Audit, and Legislative Oversight | C12: Manages the integration of findings from Supreme Audit Institutions (SAIs), the coverage of internal audit plans, and the timeliness of legislative reviews4
B13: 2.4 Reputational, Credibility, and Political Risk | C13: Mitigates credibility risk
A14: 3. Operational Resilience and Strategic Risk | C14: Governs the delivery of public programs and the capacity of governments to anticipate, prepare for, and respond to critical, large-scale crises
B15: 3.1 Program Design, Implementation, and Change Management | C15: Manages operational vulnerabilities in service delivery, including resource bottlenecks, legacy process rigidity, and organizational change management
B16: 3.2 Governance of Critical Risks and Disaster Preparedness | C16: Addresses systemic, transboundary, and cascading threats such as natural disasters, climate change disruptions, fiscal disruption, padamemics, and critical infrastructure failures
B17: 3.3 Human Capital and Talent Capacity Management | C17: Focuses on recruitment delays, key-man dependencies, critical skills gaps, and human resources planning in high-complexity environments3
A18: 4. Digital Systems and Technological Infrastructure | C18: Isolates information technology and digital assets from physical assets, reflecting the critical role of technology in modern public service delivery and the unique threats of the digital landscape
B19: 4.1 Enterprise Architecture and IT Project Governance | C19: Ensures that digital investments are aligned with organizational goals, managed through formal project frameworks, and reviewed by Architecture Review Boards (ARBs)
B20: 4.2 Cybersecurity, Information Stewardship, and Privacy | C20: Focuses on the mitigation of data breaches, ransomware attacks, insider threats, and the exfiltration of sensitive personal information
B21: 4.3 Emerging Technology and Artificial Intelligence Governance | C21: Manages the operational, compliance, and ethical risks associated with the deployment of artificial intelligence, machine learning, and automated decision-making system | E21: Data governance?
B22: 4.4 Big Data and Content Governance | C22: Manages data?
A23: 5. Environmental, Social, and Stakeholder Safeguards | C23: Eensures that government programs and investment projects avoid or mitigate adverse impacts on communities and the environment, promoting sustainable and inclusive development
B24: 5.1 Environmental Protection, Biodiversity, and Resource Efficiency | C24: Monitors project-level impacts on habitats, water resources, and pollution levels, ensuring compliance with international sustainability commitments
B25: 5.2 Social Inclusion, Human Rights, and Community Safety | C25: Manages risks related to labor conditions, gender equality, non-discrimination, community health, and the protection of vulnerable groups
B26: 5.3 Indigenous Reconciliation and Stakeholder Engagement | C26: Governs the process of meaningful, ongoing consultation, respect for traditional land rights, and the operation of responsive grievance mechanisms

Sheet New Marketecture
A1: New FreeBalance Marketecture
A3: Core Modules
A4: • core modules that can be aggregated to form comprehensive modules showing full roadmap functionality and roadmap status
A5: • modules can share functions and components (with standard some replicated components)
A6: • pricing aligns to new marketecture that is not has granular as the previous, where we can consider lower prices for lower functionality
A7: Functional Description | B7: New Marketecture | C7: Current Marketecture | D7: Development Terms | E7: Function | F7: Component | G7: S | H7: Status
A8: Policy Management | B8: =vlookup(A8,'NM Lookup'!A$15:B$33,2) -> Policy Management | C8: Not Applicable | D8: Not Applicable | E8: ='PFM Component Map'!B3 -> 1.1 Policy Management | F8: ='PFM Component Map'!C3 -> 1.1.01 Legislation Management | G8: 1 | H8: =vlookup(G8,'NM Lookup'!A$7:B$10,2) -> Low Priority
A9: Policy Management | B9: =vlookup(A9,'NM Lookup'!A$15:B$33,2) -> Policy Management | C9: Not Applicable | D9: Not Applicable | E9: ='PFM Component Map'!B4 -> 1.1 Policy Management | F9: ='PFM Component Map'!C4 -> 1.1.02 Regulation Management | G9: 1 | H9: =vlookup(G9,'NM Lookup'!A$7:B$10,2) -> Low Priority
A10: Policy Management | B10: =vlookup(A10,'NM Lookup'!A$15:B$33,2) -> Policy Management | C10: Not Applicable | D10: Not Applicable | E10: ='PFM Component Map'!B5 -> 1.1 Policy Management | F10: ='PFM Component Map'!C5 -> 1.1.03 Development Strategy & Government Goals | G10: 1 | H10: =vlookup(G10,'NM Lookup'!A$7:B$10,2) -> Low Priority
A11: Policy Management | B11: =vlookup(A11,'NM Lookup'!A$15:B$33,2) -> Policy Management | C11: Not Applicable | D11: Not Applicable | E11: ='PFM Component Map'!B6 -> 1.1 Policy Management | F11: ='PFM Component Map'!C6 -> 1.1.04 Policy Legal Framework | G11: 1 | H11: =vlookup(G11,'NM Lookup'!A$7:B$10,2) -> Low Priority
A12: Policy Management | B12: =vlookup(A12,'NM Lookup'!A$15:B$33,2) -> Policy Management | C12: Not Applicable | D12: Not Applicable | E12: ='PFM Component Map'!B7 -> 1.1 Policy Management | F12: ='PFM Component Map'!C7 -> 1.1.05 Intergovernmental Fiscal Relations | G12: 1 | H12: =vlookup(G12,'NM Lookup'!A$7:B$10,2) -> Low Priority
A13: Policy Management | B13: =vlookup(A13,'NM Lookup'!A$15:B$33,2) -> Policy Management | C13: Not Applicable | D13: Not Applicable | E13: ='PFM Component Map'!B8 -> 1.1 Policy Management | F13: ='PFM Component Map'!C8 -> 1.1.06 Fiscal Framework | G13: 1 | H13: =vlookup(G13,'NM Lookup'!A$7:B$10,2) -> Low Priority
A14: Policy Management | B14: =vlookup(A14,'NM Lookup'!A$15:B$33,2) -> Policy Management | C14: Not Applicable | D14: Not Applicable | E14: ='PFM Component Map'!B9 -> 1.1 Policy Management | F14: ='PFM Component Map'!C9 -> 1.1.07 Trend Analysis | G14: 1 | H14: =vlookup(G14,'NM Lookup'!A$7:B$10,2) -> Low Priority
A15: Policy Management | B15: =vlookup(A15,'NM Lookup'!A$15:B$33,2) -> Policy Management | C15: Not Applicable | D15: Not Applicable | E15: ='PFM Component Map'!B10 -> 1.1 Policy Management | F15: ='PFM Component Map'!C10 -> 1.1.08 Macroeconomic Forecasting | G15: 1 | H15: =vlookup(G15,'NM Lookup'!A$7:B$10,2) -> Low Priority
A16: Policy Management | B16: =vlookup(A16,'NM Lookup'!A$15:B$33,2) -> Policy Management | C16: Not Applicable | D16: Not Applicable | E16: ='PFM Component Map'!B11 -> 1.1 Policy Management | F16: ='PFM Component Map'!C11 -> 1.1.09 Policy Planning Versions | G16: 1 | H16: =vlookup(G16,'NM Lookup'!A$7:B$10,2) -> Low Priority
A17: Policy Management | B17: =vlookup(A17,'NM Lookup'!A$15:B$33,2) -> Policy Management | C17: Not Applicable | D17: Not Applicable | E17: ='PFM Component Map'!B12 -> 1.1 Policy Management | F17: ='PFM Component Map'!C12 -> 1.1.10 Policy Impact Assessment | G17: 1 | H17: =vlookup(G17,'NM Lookup'!A$7:B$10,2) -> Low Priority
A18: Policy Management | B18: =vlookup(A18,'NM Lookup'!A$15:B$33,2) -> Policy Management | C18: Not Applicable | D18: Not Applicable | E18: ='PFM Component Map'!B13 -> 1.1 Policy Management | F18: ='PFM Component Map'!C13 -> 1.1.11 Cross-Sectoral Policy Integration | G18: 1 | H18: =vlookup(G18,'NM Lookup'!A$7:B$10,2) -> Low Priority
A19: Policy Management | B19: =vlookup(A19,'NM Lookup'!A$15:B$33,2) -> Policy Management | C19: Not Applicable | D19: Not Applicable | E19: ='PFM Component Map'!B14 -> 1.1 Policy Management | F19: ='PFM Component Map'!C14 -> 1.1.12 International Commitments & Agreements | G19: 1 | H19: =vlookup(G19,'NM Lookup'!A$7:B$10,2) -> Low Priority
... A48: Budget Preperation | B48: =vlookup(A48,'NM Lookup'!A$15:B$33,2) -> Government Budget Formulation | C48: Performance Budgeting | D48: Budget Planning | E48: ='PFM Component Map'!B43 -> 1.3 Public Accounts Management | F48: ='PFM Component Map'!C43 -> 1.3.01 Accounting Regulatory Framework | G48: 4 | H48: =vlookup(G48,'NM Lookup'!A$7:B$10,2) -> Available
A49: Budget Preperation | B49: =vlookup(A49,'NM Lookup'!A$15:B$33,2) -> Government Budget Formulation | C49: Performance Budgeting | D49: Budget Planning | E49: =E574 -> 1.3 Public Accounts Management | F49: =F574 -> 1.3.01 Accounting Regulatory Framework | G49: =G574 -> 4 | H49: =H574 -> Available
A50: Budget Preperation | B50: =vlookup(A50,'NM Lookup'!A$15:B$33,2) -> Government Budget Formulation | C50: Performance Budgeting | D50: Budget Planning | E50: =E575 -> 1.3 Public Accounts Management | F50: =F575 -> 1.3.02 Accounting Policies | G50: =G575 -> 4 | H50: =H575 -> Available
A51: Budget Preperation | B51: =vlookup(A51,'NM Lookup'!A$15:B$33,2) -> Government Budget Formulation | C51: Performance Budgeting | D51: Budget Planning | E51: =E576 -> 1.3 Public Accounts Management | F51: =F576 -> 1.3.03 Accounting Codes in Chart of Accounts | G51: =G576 -> 4 | H51: =H576 -> Available
A52: Budget Preperation | B52: =vlookup(A52,'NM Lookup'!A$15:B$33,2) -> Government Budget Formulation | C52: Performance Budgeting | D52: Budget Planning | E52: =E577 -> 1.3 Public Accounts Management | F52: =F577 -> 1.3.04 Budget Classifications in Chart of Accounts | G52: =G577 -> 4 | H52: =H577 -> Available
A53: Budget Preperation | B53: =vlookup(A53,'NM Lookup'!A$15:B$33,2) -> Government Budget Formulation | C53: Performance Budgeting | D53: Budget Planning | E53: =E578 -> 1.3 Public Accounts Management | F53: =F578 -> 1.3.05 Program Classifications in Chart of Accounts | G53: =G578 -> 4 | H53: =H578 -> Available
A54: Budget Preperation | B54: =vlookup(A54,'NM Lookup'!A$15:B$33,2) -> Government Budget Formulation | C54: Performance Budgeting | D54: Budget Planning | E54: =E579 -> 1.3 Public Accounts Management | F54: =F579 -> 1.3.06 National Standards in Chart of Accounts | G54: =G579 -> 4 | H54: =H579 -> Available
A55: Budget Preperation | B55: =vlookup(A55,'NM Lookup'!A$15:B$33,2) -> Government Budget Formulation | C55: Performance Budgeting | D55: Budget Planning | E55: =E580 -> 1.3 Public Accounts Management | F55: =F580 -> 1.3.07 International Standards in Chart of Accounts | G55: =G580 -> 4 | H55: =H580 -> Available
A56: Budget Preperation | B56: =vlookup(A56,'NM Lookup'!A$15:B$33,2) -> Government Budget Formulation | C56: Performance Budgeting | D56: Budget Planning | E56: =E581 -> 1.3 Public Accounts Management | F56: =F581 -> 1.3.08 Sustainable Development Goals in Chart of Accounts | G56: =G581 -> 4 | H56: =H581 -> Available
A57: Budget Preperation | B57: =vlookup(A57,'NM Lookup'!A$15:B$33,2) -> Government Budget Formulation | C57: Performance Budgeting | D57: Budget Planning | E57: =E582 -> 1.3 Public Accounts Management | F57: =F582 -> 1.3.09 Gender, Wellbeing and Inclusion in Chart of Accounts | G57: =G582 -> 4 | H57: =H582 -> Available
A58: Budget Preperation | B58: =vlookup(A58,'NM Lookup'!A$15:B$33,2) -> Government Budget Formulation | C58: Performance Budgeting | D58: Budget Planning | E58: =E583 -> 1.3 Public Accounts Management | F58: =F583 -> 1.3.10 Reporting Objects | G58: =G583 -> 4 | H58: =H583 -> Available
A59: Budget Preperation | B59: =vlookup(A59,'NM Lookup'!A$15:B$33,2) -> Government Budget Formulation | C59: Performance Budgeting | D59: Budget Planning | E59: =E584 -> 1.3 Public Accounts Management | F59: =F584 -> 1.3.11 PEFA Assessments | G59: =G584 -> 4 | H59: =H584 -> Available
A60: Budget Preperation | B60: =vlookup(A60,'NM Lookup'!A$15:B$33,2) -> Government Budget Formulation | C60: Performance Budgeting | D60: Budget Planning | E60: =E585 -> 1.3 Public Accounts Management | F60: =F585 -> 1.3.A1 Chart of Accounts Additions | G60: =G585 -> 4 | H60: =H585 -> Available
A61: Budget Preperation | B61: =vlookup(A61,'NM Lookup'!A$15:B$33,2) -> Government Budget Formulation | C61: Performance Budgeting | D61: Budget Planning | E61: ='PFM Component Map'!B43 -> 1.3 Public Accounts Management | F61: ='PFM Component Map'!C56 -> 1.3.T1 Government Classification Transparency | G61: 1 | H61: =vlookup(G61,'NM Lookup'!A$7:B$10,2) -> Low Priority
A62: Performance and Transparency | B62: Fiscal Performance and Transparency | C62: Performance Management & Portals | D62: ? | E62: ='PFM Component Map'!B57 -> 1.4 Performance Structures & Implementation | F62: ='PFM Component Map'!C57 -> 1.4.01 Output Performance Indicators / Targets | G62: 4 | H62: =vlookup(G62,'NM Lookup'!A$7:B$10,2) -> Available
A63: Performance and Transparency | B63: Fiscal Performance and Transparency | C63: Performance Management & Portals | D63: ? | E63: ='PFM Component Map'!B58 -> 1.4 Performance Structures & Implementation | F63: ='PFM Component Map'!C58 -> 1.4.02 Chart of Goals integrated with Chart of Accounts | G63: 4 | H63: =vlookup(G63,'NM Lookup'!A$7:B$10,2) -> Available
A64: Performance and Transparency | B64: Fiscal Performance and Transparency | C64: Performance Management & Portals | D64: ? | E64: ='PFM Component Map'!B59 -> 1.4 Performance Structures & Implementation | F64: ='PFM Component Map'!C59 -> 1.4.03 Public Finance Analytics | G64: 4 | H64: =vlookup(G64,'NM Lookup'!A$7:B$10,2) -> Available
A65: Performance and Transparency | B65: Fiscal Performance and Transparency | C65: Performance Management & Portals | D65: ? | E65: ='PFM Component Map'!B60 -> 1.4 Performance Structures & Implementation | F65: ='PFM Component Map'!C60 -> 1.4.04 Public Finance Visualization | G65: 4 | H65: =vlookup(G65,'NM Lookup'!A$7:B$10,2) -> Available
A66: Performance and Transparency | B66: Fiscal Performance and Transparency | C66: Performance Management & Portals | D66: ? | E66: ='PFM Component Map'!B61 -> 1.4 Performance Structures & Implementation | F66: ='PFM Component Map'!C61 -> 1.4.05 Performance Presentation | G66: 3 | H66: =vlookup(G66,'NM Lookup'!A$7:B$10,2) -> High Priority
A67: Performance and Transparency | B67: Fiscal Performance and Transparency | C67: Performance Management & Portals | D67: ? | E67: ='PFM Component Map'!B62 -> 1.4 Performance Structures & Implementation | F67: ='PFM Component Map'!C62 -> 1.4.06 Public Finance Storytelling | G67: 1 | H67: =vlookup(G67,'NM Lookup'!A$7:B$10,2) -> Low Priority
A68: Performance and Transparency | B68: Fiscal Performance and Transparency | C68: Performance Management & Portals | D68: ? | E68: ='PFM Component Map'!B63 -> 1.4 Performance Structures & Implementation | F68: ='PFM Component Map'!C63 -> 1.4.07 Spending Reviews | G68: 1 | H68: =vlookup(G68,'NM Lookup'!A$7:B$10,2) -> Low Priority
A69: Performance and Transparency | B69: Fiscal Performance and Transparency | C69: Performance Management & Portals | D69: ? | E69: ='PFM Component Map'!B64 -> 1.4 Performance Structures & Implementation | F69: ='PFM Component Map'!C64 -> 1.4.08 Peer Benchmarking & Global Comparisons | G69: 1 | H69: =vlookup(G69,'NM Lookup'!A$7:B$10,2) -> Low Priority
...

Sheet Current Marketecture
A1: Current FreeBalance Marketecture
A3: Purpose: Map current FreeBalance Marketecture to proposed New Marketecture (does not include interfaces)
A4: • Available: whether module is available
A5: • Built-In: whether a built-in Platform functionality, not priced
A6: • Invent: invented product, really the same as a previous
A7: • 3rd: available as a 3rd party product
A8: • In New: whether part of the new marketecture
A9: • Subset: represents a subset of functionliatyin the new marketecture
A11: Marketecture
C12: Product Status
A13: Pillar | B13: Product | C13: Available | D13: Built-in | E13: Invent | F13: 3rd | G13: In New | H13: Subset
A14: GPM | B14: (GPAC) Anti-Corruption Reporting | C14: FALSE | D14: FALSE | E14: FALSE | F14: FALSE | G14: FALSE | H14: FALSE
A15: GPM | B15: (GPAM) Audit Management | C15: TRUE | D15: FALSE | E15: FALSE | F15: FALSE | G15: FALSE | H15: FALSE
A16: GPM | B16: (GPBB) Budget Book Builder | C16: TRUE | D16: FALSE | E16: FALSE | F16: FALSE | G16: FALSE | H16: TRUE
A17: GPM | B17: (GPBD) Big Data Management | C17: FALSE | D17: FALSE | E17: FALSE | F17: FALSE | G17: FALSE | H17: FALSE
A18: GPM | B18: (GPCA) Computer-Assisted Audit | C18: FALSE | D18: FALSE | E18: FALSE | F18: TRUE | G18: FALSE | H18: FALSE
A19: GPM | B19: (GPCE) President/Prime Minister Dashboard | C19: TRUE | D19: FALSE | E19: FALSE | F19: FALSE | G19: FALSE | H19: FALSE
A20: GPM | B20: (GPCM) Correspondence Management | C20: FALSE | D20: FALSE | E20: FALSE | F20: TRUE | G20: FALSE | H20: FALSE
A21: GPM | B21: (GPCO) Citizens Outreach | C21: FALSE | D21: FALSE | E21: FALSE | F21: FALSE | G21: FALSE | H21: FALSE
A22: GPM | B22: (GPCR) Customized Reporting | C22: TRUE | D22: FALSE | E22: FALSE | F22: TRUE | G22: FALSE | H22: FALSE
A23: GPM | B23: (GPCT) Court Case Tracking | C23: TRUE | D23: FALSE | E23: FALSE | F23: FALSE | G23: FALSE | H23: FALSE
A24: GPM | B24: (GPDM) FreeBalance Datamart | C24: TRUE | D24: FALSE | E24: FALSE | F24: FALSE | G24: FALSE | H24: FALSE
A25: GPM | B25: (GPMA) Management Alerts | C25: TRUE | D25: TRUE | E25: FALSE | F25: FALSE | G25: FALSE | H25: FALSE
... A71: GTM | B71: (GTTM) Treasury Management | C71: TRUE | D71: FALSE | E71: FALSE | F71: FALSE | G71: FALSE | H71: FALSE
A72: GTM | B72: (GTBR) Bank Reconciliation | C72: TRUE | D72: TRUE | E72: FALSE | F72: FALSE | G72: FALSE | H72: FALSE | J72: current price list
A73: GTM | B73: (GTBT) Bank Account Transfers[V6] | C73: TRUE | D73: FALSE | E73: FALSE | F73: FALSE | G73: FALSE | H73: FALSE
A74: GTM | B74: (GTCM) Cash Management | C74: TRUE | D74: TRUE | E74: FALSE | F74: FALSE | G74: FALSE | H74: FALSE
A75: GTM | B75: (GTDM) Debt Management | C75: TRUE | D75: FALSE | E75: FALSE | F75: FALSE | G75: FALSE | H75: FALSE
A76: GTM | B76: (GTDP) Debt Planning and Forecasting | C76: FALSE | D76: FALSE | E76: FALSE | F76: FALSE | G76: FALSE | H76: FALSE | J76: triangulate with PFMCM
A77: GTM | B77: (GTIM) Investment Management | C77: TRUE | D77: FALSE | E77: FALSE | F77: FALSE | G77: FALSE | H77: FALSE
A78: GTM | B78: (GTIT) Government Departmental Transfers | C78: TRUE | D78: TRUE | E78: FALSE | F78: FALSE | G78: FALSE | H78: FALSE
A79: GTM | B79: (GTLM) Liquidity Management | C79: FALSE | D79: FALSE | E79: FALSE | F79: FALSE | G79: FALSE | H79: FALSE
A80: GTM | B80: (GTNB) National Bank Software | C80: FALSE | D80: FALSE | E80: FALSE | F80: FALSE | G80: FALSE | H80: FALSE
A81: GTM | B81: (GTPM) Payment Management | C81: TRUE | D81: FALSE | E81: FALSE | F81: FALSE | G81: FALSE | H81: FALSE
A82: GTM | B82: (GTRM) Risk Management | C82: FALSE | D82: FALSE | E82: FALSE | F82: FALSE | G82: FALSE | H82: FALSE
A83: PEM | B83: (PECM) Contract Management | C83: TRUE | D83: FALSE | E83: FALSE | F83: FALSE | G83: FALSE | H83: FALSE
A84: PEM | B84: (PEEA) E-Auctions | C84: FALSE | D84: FALSE | E84: FALSE | F84: FALSE | G84: FALSE | H84: FALSE
A85: PEM | B85: (PEEA) E-Bidding | C85: FALSE | D85: FALSE | E85: FALSE | F85: FALSE | G85: FALSE | H85: FALSE
A86: PEM | B86: (PECT) Catalogue Management | C86: TRUE | D86: TRUE | E86: FALSE | F86: FALSE | G86: FALSE | H86: FALSE
A87: PEM | B87: (PEEP) e-Procurement Portal | C87: TRUE | D87: FALSE | E87: FALSE | F87: FALSE | G87: FALSE | H87: FALSE
...

Sheet NM Lookup
A1: New FreeBalance Marketecture
A2: Lookup
A4: Status Lookup
A5: • colour-code product status for easy reference
A6: S | B6: Status
A7: 1 | B7: Low Priority
A8: 2 | B8: Medium Priority
A9: 3 | B9: High Priority
A10: 4 | B10: Available
A12: Product Lookup
A13: • align product functional description to markecture name
A14: Description | B14: Marketecture Name | C14: To Market
A15: Assets and Inventory | B15: Asset and Inventory Lifecycle | C15: TRUE
A16: Audit | B16: Risk and Performance Audit | C16: TRUE
A17: Budget Preparation | B17: Government Budget Formulation | C17: TRUE
A18: Core Fnancials | B18: Core Financial Execution and Reporting | C18: TRUE
A19: Debt | B19: Public Debt and Guarantee Management | C19: TRUE
A20: Financial Investments | B20: Public Financial Investments | C20: TRUE
A21: Grants | B21: Transfers and Grants | C21: FALSE
A22: Human Resources | B22: Public Service Talent and Capital Human Capital | C22: TRUE
A23: Non-Tax | B23: Revenue and Receipts Mobilization | C23: TRUE
A24: Payroll | B24: Payroll and Wage Bills | C24: TRUE
A25: Performance and Transparency | B25: Fiscal Performance and Transparency | C25: TRUE
A26: Policy Management | B26: Policy Management | C26: FALSE
... A33: Treasury | B33: Treasury and Liquidity | C33: TRUE
A35: Products | B35: =counta(B15:B33) -> 19 | C35: =countif(C15:C33, TRUE) -> 15

Sheet Existing Categories
A1: Categories
A2: LOE Categories
A3: 3rd Party
A4: Integration
A5: Platform
A6: Customer Specific
A7: Services
A8: Suite
A9: New Module
A10: Non-Functional
A11: Report (new GRP Report)
A12: Report (new BIRT Report)
A13: Report (adjustment)

Sheet Concepts
A1: Component Business Model, IBM Approach, Accountability Level | C1: Government Component Mapping, FreeBalance Approach | F1: Component Business Mapping
A2: Direct | B2: Components at this level provide strategic direction and corporate policy to other components. They also facilitate collaboration with other components. | C2: D-AP | D2: Approvals | E2: Process of approving financial management steps | F2: Concept | G2: Explanation
C3: D-PS | D3: Planning & Scenarios | E3: Planning & scenario management | F3: Business Purpose | G3: Why does it exist?
C4: D-RM | D4: Reform & Modernization | E4: Definitions of policy & procedures including legal reform, Chart of Accounts, support for progressive activation | F4: Activities | G4: What simple, cohesive actions are regularly performed?
A5: Control | B5: These mid-tier components serve as checks and balances between the “direct” and “execute” levels. They monitor performance, manage exceptions and act as gatekeepers of assets and information. | C5: C- GC | D5: Government Controls | E5: Budget & commitment controls, approval workflow, segregation of duties | F5: Resources | G5: What tangible assets and human resources are required?
C6: C-ME | D6: Monitoring & Evaluation | E6: Query, analysis, forecasting, visualization | F6: Governance | G6: How are activities and resources managed?
C7: C-PM | D7: Performance Management | E7: Results-based budgeting, value-for-money, merit-based pay, Chart of Goals | F7: Business Services | G7: What is taken from and offered to other components?
C8: C-OA | D8: Oversight & Audit | E8: Oversight agency & audit functionality
A9: Execute | B9: These “boots on the ground” components provide the business actions that drive value creation in the enterprise. They process assets and information for use by other components or the end customer. | C9: E-CM | D9: E-Commerce | E9: Supports online commerce and payments, covering revenue and expenses
C10: E-FT | D10: Fiscal Transparency | E10: Transparency portals, statutory reporting
C11: E-PY | D11: Payments | E11: Supports payments and receipts, including EFT, cheques, cash & other methods not associated with e-commerce.
C12: E-PE | D12: Process Execution | E12: Primarily implements or executes a government financial process
A14: Component business model (CBM) is a technique to model and analyze an enterprise. It is a logical representation or map of business components or "building blocks" and can be depicted on a single page. It can be used to analyze the alignment of enterprise strategy with the organization's capabilities and investments, identify redundant or overlapping business capabilities, analyze sourcing options for the different components (buy or build), prioritizing transformation options and can be used to create a unified roadmap after mergers or acquisitions.

Sheet Pivot Table
A14: PFMCM Components by Pillar
A15: 1. GPM | B15: =M3 -> 67 | C15: =B15/B$23 -> 0.11985689
A16: 2. CBM | B16: =M4 -> 50 | C16: =B16/B$23 -> 0.089445438
A17: 3. PFM | B17: =M5 -> 70 | C17: =B17/B$23 -> 0.12522361
A18: 4. GTM | B18: =M6 -> 64 | C18: =B18/B$23 -> 0.11449016
A19: 5. PEM | B19: =M7 -> 87 | C19: =B19/B$23 -> 0.15563506
A20: 6. GRM | B20: =M8 -> 88 | C20: =B20/B$23 -> 0.15742397
A21: 7. CSM | B21: =M9 -> 107 | C21: =B21/B$23 -> 0.19141324
A22: 8. GSD | B22: =M10 -> 26 | C22: =B22/B$23 -> 0.046511628
B23: =SUM(B15:B22) -> 559 | C23: =SUM(C15:C22) -> 1
A26: PFMCM Components by Type
A27: Control | B27: =sum(B11:E11) -> 143 | C27: =B27/B$30 -> 0.25581395
A28: Direct | B28: =sum(F11:H11) -> 117 | C28: =B28/B$30 -> 0.20930233
A29: Execute | B29: =sum(I11:L11) -> 299 | C29: =B29/B$30 -> 0.53488372
B30: =sum(B27:B29) -> 559 | C30: =B30/B$30 -> 1
D36: =counta(A36:A68) -> 33
A72: COUNTUNIQUE of Function | B72: Type
A73: Pillar | B73: C- GC | C73: C-ME | D73: C-OA | E73: C-PM | F73: D-AP | G73: D-PS | H73: D-RM | I73: E-CM | J73: E-FT | K73: E-PE | L73: E-PY | M73: Grand Total
A74: 1. Government Performance Management | B74: 3 | C74: 2 | D74: 3 | E74: 1 | F74: 4 | G74: 2 | H74: 3 | J74: 4 | M74: 4
A75: 2. Government Compliance Management | B75: 4 | C75: 1 | D75: 3 | E75: 1 | F75: 4 | J75: 4 | K75: 3 | M75: 4
A76: 3. Public Financials Management | B76: 1 | C76: 1 | D76: 2 | E76: 1 | F76: 4 | G76: 2 | H76: 1 | J76: 4 | K76: 3 | M76: 4
A77: 4. Government Treasury Management | B77: 2 | C77: 2 | D77: 3 | F77: 3 | G77: 3 | I77: 1 | J77: 2 | K77: 2 | L77: 1 | M77: 3
A78: 5. Public Expenditure Management | B78: 4 | C78: 3 | D78: 4 | E78: 3 | F78: 4 | G78: 2 | J78: 4 | K78: 4 | M78: 4
A79: 6. Government Receipts Management | B79: 2 | C79: 1 | D79: 3 | F79: 3 | G79: 3 | I79: 3 | J79: 3 | K79: 3 | L79: 2 | M79: 3
A80: 7. Civil Service Management | B80: 3 | C80: 3 | D80: 3 | E80: 1 | F80: 6 | G80: 3 | H80: 1 | J80: 6 | K80: 4 | M80: 6
A81: 8. Government Service Delivery | I81: 3 | J81: 5 | K81: 1 | L81: 5 | M81: 5
A82: Grand Total | B82: 19 | C82: 13 | D82: 21 | E82: 7 | F82: 28 | G82: 15 | H82: 5 | I82: 7 | J82: 32 | K82: 20 | L82: 8 | M82: 33

Sheet Budget 2.0
A1: Budget 2.0
A2: • focus on budget transparency & maturity • updates since original version in green
A4: Concepts
A5: • Budget 1.0: Traditional mechanisms of budget management that are primarily internally-focused (often called “back-office”), where control and compliance are major concerns • Transitional: Increase of externally focused or “front-office” budget management where transparency, web transactions and government reporting are important characteristics but do not achieve “Web 2.0” characteristics • Budget 2.0: Social and Web 2.0 mechanisms that attempt to leverage the network effect to improve government performance and service delivery while leveraging the integration of front and back office systems
A7: Classifications
A8: Transition to Open Government
A9: Classification | B9: Closed: “1.0” | C9: Transition | D9: Open: “2.0”
A10: Transparency | B10: Access to information | C10: Documents | D10: Machine readable
A11: Data Availability | B11: Data for sale | C11: Publish as exception | D11: Publish as norm
A12: Mode | B12: Publish, audit and vetted | C12: Mixed | D12: Near real-time publishing
A13: Target | B13: Business community | C13: Civil society organizations, press | D13: Citizens
A14: Transition to Open Systems
A15: Classification | B15: Closed: “1.0” | C15: Transition | D15: Open: “2.0”
A16: Transition to Open Systems | B16: Vendor Proprietary: Intra-suite integration | C16: Industry standards support with generalized integration points | D16: Service-Oriented Architecture provides ease of integration
A17: Middleware | B17: Vendor Proprietary: customer lock-in | C17: Tactical support for open standards | D17: Full support for open standards, broad open source adoption, availability of low cost cloud deployment services
A18: Extensibility | B18: Vendor proprietary | C18: Vendor eco-system adds value | D18: All vendors and all customers add value
A20: Evaluation
A21: Transparency Mechanisms
A22: Budget 1.0 | C22: Transitional | E22: Budget 2.0
A23: 1 | B23: 2 | C23: 3 | D23: 4 | E23: 5 | F23: 6
B24: Published Documents: Formal documents like “budget book” printed through government printing agency | C24: Web Publishing: Information published to the web as web pages, documents Increasingly pro-active disclosure | E24: Open Data • Pro-active data disclosure, near real-time • Machine-readable information supporting Application Programming Interfaces (APIs) to support information mashups • Increasing amounts of non-financial data including performance information
B25: Narrative-Centric: Documents focused primarily on narrative where diagrams and photographs used to enhance narrative points | D25: Visualization-Centric: Diagrams, charts, multimedia and infographics as primary communications mechanism
C26: Citizen-Centric: Significant effort to provide information so that it is easily understood by citizens
D27: Interactive Data: Search, drill-down, data selection and output
A28: Oversight
A29: Budget 1.0 | C29: Transitional | E29: Budget 2.0
A30: Audit • Primary concern is budget compliance • Often: Internal departmental audit organizations • Often: Independent audit agencies within government | B30: Parliamentary Oversight: Parliamentary budget agencies as counterpoint to government budget organization | E30: Citizen Oversight • Enabled through pro-active disclosure, access to information, open data, machine readable data and mashups • Rise of so-called “data journalism” • Mechanisms to encourage participation including participatory budgeting, crowdsourcing
B31: Audio Visual: Hearings, debates, press conferences published via TV and web
B32: Performance Auditing: Audits matures from budget compliance to performance and risk management
A33: Press and NGO oversight: Freedom of the press and freedom of assembly
C34: Access to information: Freedom of information laws to enable petitioning government for information, formal process to manage, redact and release
B35: Cooperative Planning: Outreach to business, academics, NGOs in planning | D35: Expert Networks: Use of collaborative networks, social media for outreach to communities of experts
A36: Policy Management
A37: Budget 1.0 | C37: Transitional | E37: Budget 2.0
B38: Macro-fiscal frameworks: Methods to collect macroeconomic information and analysis to be used in developing policy | D38: Performance Management • Analysis of policy effectiveness • Results shared externally • Adjustment of programs to better achieve policy objectives | F38: Participatory Policy • Social media mechanisms to develop policy positions during elections • Social media mechanisms to develop policy positions as part of budget formulation process
B39: Policy-budget Linkages: Linkage of policy objectives to budget inputs
C40: Policy Outreach • Leveraging external stakeholders, NGOs, business groups etc. to develop policy • Often: formal methods or public hearings used
A42: Budget Formulation
A43: Budget 1.0 | C43: Transitional | E43: Budget 2.0
A44: Budget as ceremony • Top-down, bottom-up formal and informal processes resulting in budget law • Limited stakeholder engagement outside government & parliament | B44: Budget books • Publication of budget plans, government intentions, organic budget law • Often: pre-budget statement • Often: executive budget proposal | D44: Government Performance Management • Focus on non-financial measures, output and outcome results • Often: use of dashboards and scorecards • Often: performance information published on web • Often: includes accountability structure that enables management discretion, within rules, to optimize performance | F44: Participatory Budgeting: Extends budget preparation to citizens, NGOs, businesses
...

Sheet Modern Finance Ministry
A1: Modern Finance Ministry
A2: • based on IMF paper in 2015: IMF The Evolving Functions and • extended for FISC 2019
A4: IMF Guiding Principles for the Organization of a Finance Ministry
A5: 1: Unitary finance ministry
A6: 2: Flexible bureaucracy
A7: 3: Agencies to manage specialized finance functions
A8: 4: Devolution of transactional functions to line ministries
A9: 5: Focus on core policy and regulatory functions
A10: 6: Exercise a strong role in agenda setting and shaping policy across the government
A11: 7: Consolidate new functions with existing departments
A13: FreeBalance Finance Ministry Structure
A14: Culture | C14: Ministry beliefs, assumptions, value
A15: Openness | C15: Ministry transparency, collaboration
A16: Focus | C16: Ministry mandate, solution approach
A17: Controls | C17: Organizational Ministry mechanisms
A18: Strategy | C18: Ministry strategic footprint
A19: Orientation | C19: Ministry policy and process orientation
A20: Concern | C20: Drivers for Ministry action
A21: Performance | C21: Ministry performance management practices
A22: Innovation | C22: Adoption methods for Ministry innovation
A24: Finance Ministry Modernization Checklist
A25: • purposely overlap among concepts to better identify gaps • many characteristics will be somewhere in-between full tradition and full modern
A26: Culture
A27: Traditional: Segmentalist | C27: Modern: Integrative
A28: FALSE | B28: Hierarchical decision structures | C28: FALSE | D28: Horizontal coordination decision structures
A29: FALSE | B29: Important decisions with politics | C29: FALSE | D29: Important decisions evidence-driven
A30: FALSE | B30: Decision-making confined to senior levels | C30: FALSE | D30: Decision-making devolved to professional public servants
A31: FALSE | B31: Limited empowerment of Ministry public servants | C31: FALSE | D31: Empowerment of Ministry public servants
A32: FALSE | B32: Organizational silos with functional compartmentalization | C32: FALSE | D32: Program and collaborative organizational culture
A33: FALSE | B33: Leadership “command and control” | C33: FALSE | D33: Balance of top-down & bottom-up leadership
A34: FALSE | B34: Lack of data sharing across Ministry silos | C34: FALSE | D34: Data sharing across Ministry and with other Ministries
A35: FALSE | B35: Unreceptive to ideas outside Ministry | C35: FALSE | D35: Receptive to ideas outside Ministry & government
A36: Openness
A37: Traditional: Closed | C37: Modern: Open
A38: FALSE | B38: Introspective & independent thinking | C38: FALSE | D38: Communicative and interdependent thinking
A39: FALSE | B39: Financial secrecy, concern about stakeholder incentives | C39: FALSE | D39: Sharing information seen as powerful
A40: FALSE | B40: Suspicious of external expertise & information | C40: FALSE | D40: Consultative, open to external expertise & information
A41: FALSE | B41: Protect Ministry by limiting transparency | C41: FALSE | D41: Transparency by default to improve governance outcomes
A42: FALSE | B42: What data is presented in complex, untimely, irrelevant, poor quality | C42: FALSE | D42: HIgh quality timely transparent data presented accessibly
A43: FALSE | B43: Lack of timely communications | C43: FALSE | D43: Timely communications
...

Sheet COFOG
A1: United Nations Classification of the Functions of Government COFOG
A2: First Level | B2: Second Level | C2: =counta(B3:B71) -> 69
A3: 01 - General public services | B3: 01.1 - Executive and legislative organs, financial and fiscal affairs, external affairs
A4: 01 - General public services | B4: 01.2 - Foreign economic aid
A5: 01 - General public services | B5: 01.3 - General services
A6: 01 - General public services | B6: 01.4 - Basic research
A7: 01 - General public services | B7: 01.5 - R&D General public services
A8: 01 - General public services | B8: 01.6 - General public services n.e.c.
A9: 01 - General public services | B9: 01.7 - Public debt transactions
A10: 01 - General public services | B10: 01.8 - Transfers of a general character between different levels of government
A11: 02 – Defence | B11: 02.1 - Military defence
A12: 02 – Defence | B12: 02.2 - Civil defence
A13: 02 – Defence | B13: 02.3 - Foreign military aid
A14: 02 – Defence | B14: 02.4 - R&D Defence
... A71: 10 - Social protection, | B71: 10.9 - Social protection n.e.c.

Sheet Treasury Reference Model
B1: World Bank Treasury Reference Model, 2001
B2: Subordinate Units | C2: Spending & Revenue Collection Agencies | D2: MoF Budget Accounting | E2: MoF Cash Management | F2: MoF Debt Management | G2: MoF Budget Management | H2: Central Bank | I2: Commercial Banks | J2: Donor Agencies | K2: Taxpayers
A3: 1. Budget Authorization Management | B3: Record, receive | C3: Budget allotments | G3: Budget, allocations, appropriations
B4: Record, receive | C4: Sub-warrants | G4: Warrant allocations
A5: 2. Commitment of Funds | B5: Permission to commit | C5: Approve | D5: Record in system | E5: Cash position | G5: Revised limits & warrants
A6: 3. Payments and Receipts Management | B6: Goods receive
A7: 3.1 Payments | B7: Request for payment | C7: Approve | D7: Record in system | E7: Payment instructions | H7: Payments to creditors | I7: Receive, record
A8: 3.2 Receipts | B8: Review, reconcile | C8: Review, reconcile | D8: Record in system | H8: Receipts deposit | I8: Tax, non-tax receipts | K8: Tax, non-tax receipts
A9: 4. Cash Management | B9: Cash & revenue forecasts | C9: Review, consolidate | E9: Prepare overall cash requirements | F9: Debt service | H9: Cash balances
A10: 5. Debt and Aid Management
A11: 5.1 Debt Management | C11: Record & monitor | D11: Loans, grants, in-kind receipts | F11: Record, receive new debt | G11: Review, revise limits, warrants, borrowing req's | H11: Loan & grant agreements
A12: 5.2 Aid Management | C12: Record & monitor | D12: Loans, grants, in-kind receipts | F12: Record, receive new aid | J12: Aid agreements
A13: 6. Budget Review and Fiscal Reporting
A14: 6.1 Budget Review | G14: Budget reviews, revise limits and warrants
A15: 6.2 Fiscal Reporting | B15: Project, program status reports | C15: Project, program status reports | D15: Overall revenue & expenditure position | G15: Fiscal Reports

Sheet FMIS
A1: World Bank FMIS Core/Non Core
A2: F: FMIS Core | B2: T: Treasury Systems | C2: General Ledger
C3: Accounts Payable
C4: Accounts Receivable
C5: Commitment Management
C6: Cash Management
C7: Financial Reporting
D8: • management of budget authorizations/releases
D9: • commitment of funds
D10: • payment/revenue management (mostly based on treasury single account)
D11: • cash forecasting and management
D12: • accounting and reporting
B13: B: Budget Systems | C13: Budget Formulation
C14: Public Investment Management
D15: • medium term frameworks (e.g. MTFF, MTBF, MTEF)
D16: • program based budgeting
D17: • performance informed budgeting
A18: O: Other | C18: Personnel management
C19: Payroll
C20: Revenue Administrations (Tax and Customs)
C21: Public procurement
C22: Inventory Management
C23: Debt Management
C24: Property Management
C25: Performance Monitoring
D26: • revenue collection (mainly interfaces with tax and customs systems)
D27: • debt management (covering both domestic and external debt)
D28: • procurement/purchasing (tracking all payments after contract signature)
D29: • asset and inventory management
D30: • Human Resources Management Information System (HRMIS)
A31: P: Prepatory Work | B31: For T or F | D31: • accounting/financial reporting reforms, including compliance with International Public Sector Accounting Standards (IPSAS)
D32: • budgeting and macro-economic forecasting in the Ministry of Finance/Economy
D33: • establishment of Treasury Single Account (TSA)
D34: • improvement of budget classification (BC) and unified chart of accounts (CoA)
A35: B: Beyond FMIS | B35: typically outside FMIS | C35: Policy Development and Review
C36: Publishing/Web Portal
C37: Audit and Evaluation

Sheet IMF Budget Cycle
A1: IMF Budget Cycle
A2: 0. Legal Framework | B2: • Developing Legal Frameworks To Promote Fiscal Responsibility
A3: 1. Fiscal Framework | B3: • Integrating Fiscal Risk Management into the Budget Cycle • The Design of National Fiscal Frameworks and their Budgetary Impact
A4: 2. Budget Preparation | B4: Guidelines for Public Expenditure Management • Introduction • The Expenditure Aggregates and Data Sources • Budget Preparation
A5: 3. Budget Execution | B5: Guidelines for Public Expenditure Management • Budget Execution • Cash Planning and Management
A6: 4. Accounting and Reporting | B6: • Budgeting, accounting, and reporting • Government Budget and Accounting Systems
A7: 5. Control and Audit | B7: • Expenditure Control: Key Features, Stages, and Actors

Sheet International Assessments
A1: International Public Finance Assessments
A3: Public Expenditure and Financial Accountability (PEFA)
A4: Pillar | B4: Performance Indicator
A5: I. Budget Reliability | B5: PI - 1. Aggregate expenditure outturn
B6: • 1.1 Aggregate expenditure outturn
B7: PI - 2. Expenditure composition outturn
B8: • 2.1 Expenditure composition outturn by function • 2.2 Expenditure composition outturn by economic type • 2.3 Expenditure from contingency reserves
B9: PI - 3. Revenue outturn
B10: • 3.1 Aggregate revenue outturn • 3 .2 Revenue composition outturn
A11: II. Transparency of Public Finances | B11: PI - 4. Budget classification
B12: • 4.1 Budget classification
B13: PI - 5. Budget documentation
B14: • 5.1 Budget documentation
B15: PI - 6. Central government operations outside financial reports
B16: • 6.1 Expenditure outside financial reports • 6.2 Revenue outside financial reports • 6.3 Financial reports of extrabudgetary units
B17: PI - 7. Transfers to subnational governments
B18: • 7.1 System for allocating transfers • 7.2 Timeliness of information on transfers
B19: PI - 8. Performance information for service delivery
B20: • 8.1 Performance plans for service delivery • 8.2 Performance achieved for service delivery • 8.3 Resources received by service delivery units • 8.4 Performance evaluation for service delivery
B21: PI - 9. Public access to fiscal information
B22: • 9.1 Public access to fiscal information
A23: III. Management of Assets and Liabilities | B23: PI - 10. Fiscal risk reporting
B24: • 10.1 Monitoring of public corporations • 10.2 Monitoring of subnational governments • 10.3 Contingent liabilities and other fiscal risks
B25: PI - 11. Public investment management
B26: • 11.1 Economic analysis of investment proposals • 11.2 Investment project selection • 11.3 Investment project costing • 11.4 Investment project monitoring
B27: PI - 12. Public asset management
B28: • 12.1 Financial asset monitoring • 12.2 Nonfinancial asset monitoring • 12.3 Transparency of asset disposal
B29: PI - 13. Debt management
B30: • 13.1 Recording and reporting of debt and guarantees • 13.2 Approval of debt and guarantees • 13.3 Debt management strategy
A31: IV. Policy-based Fiscal Strategy & Budgeting | B31: PI - 14. Macroeconomic and fiscal forecasting
B32: • 14.1 Macroeconomic forecasts • 14.2 Fiscal forecasts • 14.3 Macrofiscal sensitivity analysis
B33: PI - 15. Fiscal strategy
B34: • 15.1 Fiscal impact of policy proposals • 15.2 Fiscal strategy adoption • 15.3 Reporting on fiscal outcomes
B35: PI - 16. Medium-term perspective in expenditure budgeting
